Workbook

Sheet Service prices
A1: Service | B1: Description of Work Included | C1: Pricing Method | D1: Unit Label | E1: Min Qty | F1: Subcontractor Minimum Payout | G1: Include | H1: Base Rate per Unit | I1: Volume Discount Threshold | J1: Volume Discount | K1: Input | L1: Cost | M1: Markup | N1: Customer Selling Price
A2: General Handyman Visit | B2: General repairs and punch-list work | C2: Per Unit | D2: Hour | E2: 1 | F2: 70 | G2: 1 | H2: 70 | I2: 1 | J2: 60 | K2: 4 | L2: =F2+IF((I2>G2),IF(K2>G2,(K2-G2)*H2,0),IF(K2>I2,(K2-I2),0)*J2) -> 250 | M2: =IF(L2<'Marketplace Rules'!$A$4,'Marketplace Rules'!$B$4,IF(L2<'Marketplace Rules'!$A$5,'Marketplace Rules'!$B$5,IF(L2<'Marketplace Rules'!$A$6,'Marketplace Rules'!$B$6,'Marketplace Rules'!$B$7)))-1 -> 0.15 | N2: =L2*(1+M2) -> 287.5
A3: Drywall Patch (Small) | B3: Repair nail holes, anchors, dents up to 2" | C3: Per Unit | D3: Hole | E3: 1 | F3: 70 | G3: 3 | H3: =F3/G3 -> 23.333333 | I3: 11 | J3: 10 | K3: 4 | L3: =F3+IF((I3>G3),IF(K3>G3,(K3-G3)*H3,0),IF(K3>I3,(K3-I3),0)*J3) -> 93.333333 | M3: =IF(L3<'Marketplace Rules'!$A$4,'Marketplace Rules'!$B$4,IF(L3<'Marketplace Rules'!$A$5,'Marketplace Rules'!$B$5,IF(L3<'Marketplace Rules'!$A$6,'Marketplace Rules'!$B$6,'Marketplace Rules'!$B$7)))-1 -> 0.15 | N3: 129
A4: Medium Drywall Repair | B4: Repair holes 2–8", mud, sand, prime | C4: Per Unit | D4: Hole | E4: 1 | F4: 80 | G4: 1 | H4: 75 | I4: 5 | J4: 50 | K4: 4 | L4: =F4+IF((I4>G4),IF(K4>G4,(K4-G4)*H4,0),IF(K4>I4,(K4-I4),0)*J4) -> 305 | M4: =IF(L4<'Marketplace Rules'!$A$4,'Marketplace Rules'!$B$4,IF(L4<'Marketplace Rules'!$A$5,'Marketplace Rules'!$B$5,IF(L4<'Marketplace Rules'!$A$6,'Marketplace Rules'!$B$6,'Marketplace Rules'!$B$7)))-1 -> 0.15 | N4: 149
A5: Large Drywall Repair | B5: Replace drywall sections, tape, finish | C5: Request Quote | F5: Quote | G5: Per repair | H5: Based on SF | I5: Room discounts | M5: =IF(L5<'Marketplace Rules'!$A$4,'Marketplace Rules'!$B$4,IF(L5<'Marketplace Rules'!$A$5,'Marketplace Rules'!$B$5,IF(L5<'Marketplace Rules'!$A$6,'Marketplace Rules'!$B$6,'Marketplace Rules'!$B$7)))-1 -> 0.15 | N5: $399–1,800
A6: Wallpaper Removal | B6: Remove wallpaper and adhesive residue | C6: Per Unit | D6: Sq-Ft | E6: 1 | F6: 175 | G6: 100 | H6: 1.5 | I6: 500 | J6: =H6*(1-0.1) -> 1.35 | K6: 100 | L6: =F6+IF((I6>G6),IF(K6>G6,(K6-G6)*H6,0),IF(K6>I6,(K6-I6),0)*J6) -> 175 | M6: =IF(L6<'Marketplace Rules'!$A$4,'Marketplace Rules'!$B$4,IF(L6<'Marketplace Rules'!$A$5,'Marketplace Rules'!$B$5,IF(L6<'Marketplace Rules'!$A$6,'Marketplace Rules'!$B$6,'Marketplace Rules'!$B$7)))-1 -> 0.15 | N6: 299
A7: Interior Painting | B7: Prep and paint walls | C7: Per Unit | D7: Sq-Ft | E7: 1 | F7: 175 | G7: 100 | H7: $1–1.50/SF | I7: Whole-house pricing | M7: =IF(L7<'Marketplace Rules'!$A$4,'Marketplace Rules'!$B$4,IF(L7<'Marketplace Rules'!$A$5,'Marketplace Rules'!$B$5,IF(L7<'Marketplace Rules'!$A$6,'Marketplace Rules'!$B$6,'Marketplace Rules'!$B$7)))-1 -> 0.15 | N7: 299
A8: Baseboards & Trim | B8: Install or replace trim and moldings | C8: Per Unit | D8: Linear Feet | E8: 1 | F8: 120 | G8: 30 | H8: 3 | I8: 200 | J8: =H8*0.9 -> 2.7 | K8: 100 | L8: =F8+IF((I8>G8),IF(K8>G8,(K8-G8)*H8,0),IF(K8>I8,(K8-I8),0)*J8) -> 330 | M8: =IF(L8<'Marketplace Rules'!$A$4,'Marketplace Rules'!$B$4,IF(L8<'Marketplace Rules'!$A$5,'Marketplace Rules'!$B$5,IF(L8<'Marketplace Rules'!$A$6,'Marketplace Rules'!$B$6,'Marketplace Rules'!$B$7)))-1 -> 0.15 | N8: 199
A9: Weather Stripping | B9: Replace worn seals around doors/windows | C9: Per Unit | D9: Windows/doors | E9: 1 | F9: 70 | G9: 3 | H9: 12 | I9: 10 | J9: =H9*0.9 -> 10.8 | K9: 5 | L9: =F9+IF((I9>G9),IF(K9>G9,(K9-G9)*H9,0),IF(K9>I9,(K9-I9),0)*J9) -> 94 | M9: =IF(L9<'Marketplace Rules'!$A$4,'Marketplace Rules'!$B$4,IF(L9<'Marketplace Rules'!$A$5,'Marketplace Rules'!$B$5,IF(L9<'Marketplace Rules'!$A$6,'Marketplace Rules'!$B$6,'Marketplace Rules'!$B$7)))-1 -> 0.15 | N9: 129
A10: move | B10: Install knobs, pulls, hinges | C10: Per Unit | D10: pieces | E10: 1 | F10: 70 | G10: 10 | H10: 5 | I10: 25 | J10: =H10*0.9 -> 4.5 | K10: 5 | L10: =F10+IF((I10>G10),IF(K10>G10,(K10-G10)*H10,0),IF(K10>I10,(K10-I10),0)*J10) -> 70 | M10: =IF(L10<'Marketplace Rules'!$A$4,'Marketplace Rules'!$B$4,IF(L10<'Marketplace Rules'!$A$5,'Marketplace Rules'!$B$5,IF(L10<'Marketplace Rules'!$A$6,'Marketplace Rules'!$B$6,'Marketplace Rules'!$B$7)))-1 -> 0.15 | N10: 129
A11: Light Fixture Replacement | B11: Replace existing light fixture | C11: Per Unit | D11: Fixture | E11: 1 | F11: 70 | G11: 1 | H11: 55 | I11: 5 | J11: =H11*0.9 -> 49.5 | K11: 5 | L11: =F11+IF((I11>G11),IF(K11>G11,(K11-G11)*H11,0),IF(K11>I11,(K11-I11),0)*J11) -> 290 | M11: =IF(L11<'Marketplace Rules'!$A$4,'Marketplace Rules'!$B$4,IF(L11<'Marketplace Rules'!$A$5,'Marketplace Rules'!$B$5,IF(L11<'Marketplace Rules'!$A$6,'Marketplace Rules'!$B$6,'Marketplace Rules'!$B$7)))-1 -> 0.15 | N11: 149
A12: Ceiling Fan Replacement | B12: Replace existing fan | C12: Per Unit | D12: Fan | E12: 1 | F12: 90 | G12: 1 | H12: 75 | I12: 4 | J12: =H12*0.9 -> 67.5 | K12: 5 | L12: =F12+IF((I12>G12),IF(K12>G12,(K12-G12)*H12,0),IF(K12>I12,(K12-I12),0)*J12) -> 390 | M12: =IF(L12<'Marketplace Rules'!$A$4,'Marketplace Rules'!$B$4,IF(L12<'Marketplace Rules'!$A$5,'Marketplace Rules'!$B$5,IF(L12<'Marketplace Rules'!$A$6,'Marketplace Rules'!$B$6,'Marketplace Rules'!$B$7)))-1 -> 0.15 | N12: 179
A13: Outlet/Switch Replacement | B13: Replace existing devices | C13: Per Unit | D13: Device | E13: 1 | F13: 70 | G13: 4 | H13: 11 | I13: 20 | J13: =H13*0.9 -> 9.9 | K13: 5 | L13: =F13+IF((I13>G13),IF(K13>G13,(K13-G13)*H13,0),IF(K13>I13,(K13-I13),0)*J13) -> 81 | M13: =IF(L13<'Marketplace Rules'!$A$4,'Marketplace Rules'!$B$4,IF(L13<'Marketplace Rules'!$A$5,'Marketplace Rules'!$B$5,IF(L13<'Marketplace Rules'!$A$6,'Marketplace Rules'!$B$6,'Marketplace Rules'!$B$7)))-1 -> 0.15 | N13: 129
A14: Smart Device Installation | B14: Install cameras, thermostats, doorbells | C14: Per Unit | D14: Device | E14: 1 | F14: 80 | G14: 1 | H14: 45 | I14: 5 | J14: =H14*0.9 -> 40.5 | K14: 5 | L14: =F14+IF((I14>G14),IF(K14>G14,(K14-G14)*H14,0),IF(K14>I14,(K14-I14),0)*J14) -> 260 | M14: =IF(L14<'Marketplace Rules'!$A$4,'Marketplace Rules'!$B$4,IF(L14<'Marketplace Rules'!$A$5,'Marketplace Rules'!$B$5,IF(L14<'Marketplace Rules'!$A$6,'Marketplace Rules'!$B$6,'Marketplace Rules'!$B$7)))-1 -> 0.15 | N14: 149
A15: Smoke/CO Detectors | B15: Install replacement detectors | C15: Per Unit | D15: Detector | E15: 1 | F15: 70 | G15: 4 | H15: 12 | I15: 10 | J15: =H15*0.9 -> 10.8 | K15: 5 | L15: =F15+IF((I15>G15),IF(K15>G15,(K15-G15)*H15,0),IF(K15>I15,(K15-I15),0)*J15) -> 82 | M15: =IF(L15<'Marketplace Rules'!$A$4,'Marketplace Rules'!$B$4,IF(L15<'Marketplace Rules'!$A$5,'Marketplace Rules'!$B$5,IF(L15<'Marketplace Rules'!$A$6,'Marketplace Rules'!$B$6,'Marketplace Rules'!$B$7)))-1 -> 0.15 | N15: 129
A16: Faucet Replacement | B16: Replace existing faucet | C16: Per Unit | D16: Faucet | E16: 1 | F16: 90 | G16: 1 | H16: 75 | I16: 3 | J16: =H16*0.9 -> 67.5 | K16: 5 | L16: =F16+IF((I16>G16),IF(K16>G16,(K16-G16)*H16,0),IF(K16>I16,(K16-I16),0)*J16) -> 390 | M16: =IF(L16<'Marketplace Rules'!$A$4,'Marketplace Rules'!$B$4,IF(L16<'Marketplace Rules'!$A$5,'Marketplace Rules'!$B$5,IF(L16<'Marketplace Rules'!$A$6,'Marketplace Rules'!$B$6,'Marketplace Rules'!$B$7)))-1 -> 0.15 | N16: 179
A17: Showerhead Installation | B17: Replace showerhead | C17: Per Unit | D17: Unit | E17: 1 | F17: 70 | G17: 1 | H17: 25 | I17: 5 | J17: =H17*0.9 -> 22.5 | K17: 5 | L17: =F17+IF((I17>G17),IF(K17>G17,(K17-G17)*H17,0),IF(K17>I17,(K17-I17),0)*J17) -> 170 | M17: =IF(L17<'Marketplace Rules'!$A$4,'Marketplace Rules'!$B$4,IF(L17<'Marketplace Rules'!$A$5,'Marketplace Rules'!$B$5,IF(L17<'Marketplace Rules'!$A$6,'Marketplace Rules'!$B$6,'Marketplace Rules'!$B$7)))-1 -> 0.15 | N17: 129
A18: Toilet Repair | B18: Replace internal toilet components | C18: Per Unit | D18: Toilet | E18: 1 | F18: 80 | G18: 1 | H18: 60 | I18: 3 | J18: =H18*0.9 -> 54 | K18: 5 | L18: =F18+IF((I18>G18),IF(K18>G18,(K18-G18)*H18,0),IF(K18>I18,(K18-I18),0)*J18) -> 320 | M18: =IF(L18<'Marketplace Rules'!$A$4,'Marketplace Rules'!$B$4,IF(L18<'Marketplace Rules'!$A$5,'Marketplace Rules'!$B$5,IF(L18<'Marketplace Rules'!$A$6,'Marketplace Rules'!$B$6,'Marketplace Rules'!$B$7)))-1 -> 0.15 | N18: 149
A19: Recaulking | B19: Remove and replace caulk | C19: Per Unit | D19: Packag | E19: 1 | F19: 80 | G19: 1 | H19: 30 | I19: Whole bath package | M19: =IF(L19<'Marketplace Rules'!$A$4,'Marketplace Rules'!$B$4,IF(L19<'Marketplace Rules'!$A$5,'Marketplace Rules'!$B$5,IF(L19<'Marketplace Rules'!$A$6,'Marketplace Rules'!$B$6,'Marketplace Rules'!$B$7)))-1 -> 0.15 | N19: 149
A20: TV Mounting | B20: Install mount and hang TV | C20: Per Unit | D20: TV | E20: 1 | F20: 90 | G20: 1 | H20: 75 | I20: 4 | J20: =H20*0.9 -> 67.5 | K20: 5 | L20: =F20+IF((I20>G20),IF(K20>G20,(K20-G20)*H20,0),IF(K20>I20,(K20-I20),0)*J20) -> 390 | M20: =IF(L20<'Marketplace Rules'!$A$4,'Marketplace Rules'!$B$4,IF(L20<'Marketplace Rules'!$A$5,'Marketplace Rules'!$B$5,IF(L20<'Marketplace Rules'!$A$6,'Marketplace Rules'!$B$6,'Marketplace Rules'!$B$7)))-1 -> 0.15 | N20: 179
A21: Blinds & Curtains | B21: Install rods, blinds, shades | C21: Per Unit | D21: Window | E21: 1 | F21: 80 | G21: 3 | H21: 15 | I21: 10 | J21: =H21*0.9 -> 13.5 | K21: 5 | L21: =F21+IF((I21>G21),IF(K21>G21,(K21-G21)*H21,0),IF(K21>I21,(K21-I21),0)*J21) -> 110 | M21: =IF(L21<'Marketplace Rules'!$A$4,'Marketplace Rules'!$B$4,IF(L21<'Marketplace Rules'!$A$5,'Marketplace Rules'!$B$5,IF(L21<'Marketplace Rules'!$A$6,'Marketplace Rules'!$B$6,'Marketplace Rules'!$B$7)))-1 -> 0.15 | N21: 149
A22: Mirrors & Artwork | B22: Secure mounting of décor | C22: Per Unit | D22: Item | E22: 1 | F22: 70 | G22: 3 | H22: 10 | I22: 10 | J22: =H22*0.9 -> 9 | K22: 5 | L22: =F22+IF((I22>G22),IF(K22>G22,(K22-G22)*H22,0),IF(K22>I22,(K22-I22),0)*J22) -> 90 | M22: =IF(L22<'Marketplace Rules'!$A$4,'Marketplace Rules'!$B$4,IF(L22<'Marketplace Rules'!$A$5,'Marketplace Rules'!$B$5,IF(L22<'Marketplace Rules'!$A$6,'Marketplace Rules'!$B$6,'Marketplace Rules'!$B$7)))-1 -> 0.15 | N22: 129
A23: Shelving Installation | B23: Install shelving systems | C23: Per Unit | D23: Shelve | E23: 1 | F23: 80 | G23: 1 | H23: 35 | I23: 5 | J23: =H23*0.9 -> 31.5 | K23: 5 | L23: =F23+IF((I23>G23),IF(K23>G23,(K23-G23)*H23,0),IF(K23>I23,(K23-I23),0)*J23) -> 220 | M23: =IF(L23<'Marketplace Rules'!$A$4,'Marketplace Rules'!$B$4,IF(L23<'Marketplace Rules'!$A$5,'Marketplace Rules'!$B$5,IF(L23<'Marketplace Rules'!$A$6,'Marketplace Rules'!$B$6,'Marketplace Rules'!$B$7)))-1 -> 0.15 | N23: 149
A24: Grab Bars | B24: Install safety grab bars | C24: Per Unit | D24: Bar | E24: 1 | F24: 80 | G24: 1 | H24: 45 | I24: 4 | J24: =H24*0.9 -> 40.5 | K24: 5 | L24: =F24+IF((I24>G24),IF(K24>G24,(K24-G24)*H24,0),IF(K24>I24,(K24-I24),0)*J24) -> 260 | M24: =IF(L24<'Marketplace Rules'!$A$4,'Marketplace Rules'!$B$4,IF(L24<'Marketplace Rules'!$A$5,'Marketplace Rules'!$B$5,IF(L24<'Marketplace Rules'!$A$6,'Marketplace Rules'!$B$6,'Marketplace Rules'!$B$7)))-1 -> 0.15 | N24: 149
A25: Furniture Assembly | B25: Assemble customer-provided furniture | C25: Per Unit | D25: Pricing | E25: 1 | F25: 90 | G25: 1 | H25: Complexity based | I25: Bundle pricing | M25: =IF(L25<'Marketplace Rules'!$A$4,'Marketplace Rules'!$B$4,IF(L25<'Marketplace Rules'!$A$5,'Marketplace Rules'!$B$5,IF(L25<'Marketplace Rules'!$A$6,'Marketplace Rules'!$B$6,'Marketplace Rules'!$B$7)))-1 -> 0.15 | N25: 179
A26: Door Repairs | B26: Adjust or repair doors | C26: Per Unit | D26: Door | E26: 1 | F26: 80 | G26: 1 | H26: 60 | I26: 5 | J26: =H26*0.9 -> 54 | K26: 5 | L26: =F26+IF((I26>G26),IF(K26>G26,(K26-G26)*H26,0),IF(K26>I26,(K26-I26),0)*J26) -> 320 | M26: =IF(L26<'Marketplace Rules'!$A$4,'Marketplace Rules'!$B$4,IF(L26<'Marketplace Rules'!$A$5,'Marketplace Rules'!$B$5,IF(L26<'Marketplace Rules'!$A$6,'Marketplace Rules'!$B$6,'Marketplace Rules'!$B$7)))-1 -> 0.15 | N26: 149
A27: Lock Installation | B27: Install locksets/deadbolts | C27: Per Unit | D27: Lock | E27: 1 | F27: 80 | G27: 1 | H27: 35 | I27: 5 | J27: =H27*0.9 -> 31.5 | K27: 5 | L27: =F27+IF((I27>G27),IF(K27>G27,(K27-G27)*H27,0),IF(K27>I27,(K27-I27),0)*J27) -> 220 | M27: =IF(L27<'Marketplace Rules'!$A$4,'Marketplace Rules'!$B$4,IF(L27<'Marketplace Rules'!$A$5,'Marketplace Rules'!$B$5,IF(L27<'Marketplace Rules'!$A$6,'Marketplace Rules'!$B$6,'Marketplace Rules'!$B$7)))-1 -> 0.15 | N27: 149
A28: Window Screen Repair | B28: Replace screen mesh/frame | C28: Per Unit | D28: Screen | E28: 1 | F28: 70 | G28: 2 | H28: 10 | I28: 10 | J28: =H28*0.9 -> 9 | K28: 5 | L28: =F28+IF((I28>G28),IF(K28>G28,(K28-G28)*H28,0),IF(K28>I28,(K28-I28),0)*J28) -> 100 | M28: =IF(L28<'Marketplace Rules'!$A$4,'Marketplace Rules'!$B$4,IF(L28<'Marketplace Rules'!$A$5,'Marketplace Rules'!$B$5,IF(L28<'Marketplace Rules'!$A$6,'Marketplace Rules'!$B$6,'Marketplace Rules'!$B$7)))-1 -> 0.15 | N28: 129
A29: Pet Door Installation | B29: Cut opening and install pet door | C29: Per Unit | D29: Pet Door | E29: 1 | F29: 175 | G29: 1 | H29: 175 | I29: N/A | M29: =IF(L29<'Marketplace Rules'!$A$4,'Marketplace Rules'!$B$4,IF(L29<'Marketplace Rules'!$A$5,'Marketplace Rules'!$B$5,IF(L29<'Marketplace Rules'!$A$6,'Marketplace Rules'!$B$6,'Marketplace Rules'!$B$7)))-1 -> 0.15 | N29: 299
A30: Gutter Cleaning | B30: Remove debris and flush downspouts | C30: Per Unit | D30: LF | E30: 1 | F30: 120 | G30: 150 | H30: 0.4 | I30: 300 | J30: =H30*0.9 -> 0.36 | K30: 5 | L30: =F30+IF((I30>G30),IF(K30>G30,(K30-G30)*H30,0),IF(K30>I30,(K30-I30),0)*J30) -> 120 | M30: =IF(L30<'Marketplace Rules'!$A$4,'Marketplace Rules'!$B$4,IF(L30<'Marketplace Rules'!$A$5,'Marketplace Rules'!$B$5,IF(L30<'Marketplace Rules'!$A$6,'Marketplace Rules'!$B$6,'Marketplace Rules'!$B$7)))-1 -> 0.15 | N30: 199
A31: Pressure Washing | B31: Wash surfaces using pressure equipment | C31: Per Unit | D31: Sq-Ft | F31: 150 | G31: 1000 | H31: 0.1 | I31: 5000 | J31: =H31*0.9 -> 0.09 | K31: 5 | L31: =F31+IF((I31>G31),IF(K31>G31,(K31-G31)*H31,0),IF(K31>I31,(K31-I31),0)*J31) -> 150 | M31: =IF(L31<'Marketplace Rules'!$A$4,'Marketplace Rules'!$B$4,IF(L31<'Marketplace Rules'!$A$5,'Marketplace Rules'!$B$5,IF(L31<'Marketplace Rules'!$A$6,'Marketplace Rules'!$B$6,'Marketplace Rules'!$B$7)))-1 -> 0.15 | N31: 249
A32: Fence Repairs | B32: Replace pickets and hardware | C32: Per Unit | D32: Picket | F32: 120 | G32: 5 | H32: 10 | I32: 20 | J32: =H32*0.9 -> 9 | K32: 5 | L32: =F32+IF((I32>G32),IF(K32>G32,(K32-G32)*H32,0),IF(K32>I32,(K32-I32),0)*J32) -> 120 | M32: =IF(L32<'Marketplace Rules'!$A$4,'Marketplace Rules'!$B$4,IF(L32<'Marketplace Rules'!$A$5,'Marketplace Rules'!$B$5,IF(L32<'Marketplace Rules'!$A$6,'Marketplace Rules'!$B$6,'Marketplace Rules'!$B$7)))-1 -> 0.15 | N32: 199
A33: Deck Board Replacement | B33: Replace damaged deck boards | C33: Per Unit | D33: Quote | F33: 150 | G33: 3 | H33: $25/board | I33: Large projects quoted | M33: =IF(L33<'Marketplace Rules'!$A$4,'Marketplace Rules'!$B$4,IF(L33<'Marketplace Rules'!$A$5,'Marketplace Rules'!$B$5,IF(L33<'Marketplace Rules'!$A$6,'Marketplace Rules'!$B$6,'Marketplace Rules'!$B$7)))-1 -> 0.15 | N33: 249
A34: Tile Replacement | B34: Replace damaged tiles | C34: Per Unit | D34: Tile | F34: 80 | G34: 3 | H34: 15 | I34: 20 | J34: =H34*0.9 -> 13.5 | K34: 5 | L34: =F34+IF((I34>G34),IF(K34>G34,(K34-G34)*H34,0),IF(K34>I34,(K34-I34),0)*J34) -> 110 | M34: =IF(L34<'Marketplace Rules'!$A$4,'Marketplace Rules'!$B$4,IF(L34<'Marketplace Rules'!$A$5,'Marketplace Rules'!$B$5,IF(L34<'Marketplace Rules'!$A$6,'Marketplace Rules'!$B$6,'Marketplace Rules'!$B$7)))-1 -> 0.15 | N34: 149
A35: Regrouting | B35: Remove and replace grout | C35: Per Unit | D35: Sq-Ft | F35: 150 | G35: 100 | H35: 1 | I35: 500 | J35: =H35*0.9 -> 0.9 | K35: 5 | L35: =F35+IF((I35>G35),IF(K35>G35,(K35-G35)*H35,0),IF(K35>I35,(K35-I35),0)*J35) -> 150 | M35: =IF(L35<'Marketplace Rules'!$A$4,'Marketplace Rules'!$B$4,IF(L35<'Marketplace Rules'!$A$5,'Marketplace Rules'!$B$5,IF(L35<'Marketplace Rules'!$A$6,'Marketplace Rules'!$B$6,'Marketplace Rules'!$B$7)))-1 -> 0.15 | N35: 249
A36: Carpet Stretching | B36: Re-stretch loose carpet | C36: Per Unit | D36: Room | F36: 150 | G36: One room | H36: 80 | I36: Whole-house discount | M36: =IF(L36<'Marketplace Rules'!$A$4,'Marketplace Rules'!$B$4,IF(L36<'Marketplace Rules'!$A$5,'Marketplace Rules'!$B$5,IF(L36<'Marketplace Rules'!$A$6,'Marketplace Rules'!$B$6,'Marketplace Rules'!$B$7)))-1 -> 0.15 | N36: 249
A37: Window Repairs | B37: Repair balances, tracks, hardware | C37: Per Unit | D37: Window | F37: 80 | G37: First window | H37: 50 | I37: 5 | J37: =H37*0.9 -> 45 | K37: 5 | L37: =F37+IF((I37>G37),IF(K37>G37,(K37-G37)*H37,0),IF(K37>I37,(K37-I37),0)*J37) -> 80 | M37: =IF(L37<'Marketplace Rules'!$A$4,'Marketplace Rules'!$B$4,IF(L37<'Marketplace Rules'!$A$5,'Marketplace Rules'!$B$5,IF(L37<'Marketplace Rules'!$A$6,'Marketplace Rules'!$B$6,'Marketplace Rules'!$B$7)))-1 -> 0.15 | N37: 149
A38: Closet Shelving | B38: Install closet organization systems | C38: Per Unit | D38: Pricin | F38: 175 | G38: Basic system | H38: Custom | I38: Multi-closet pricing | M38: =IF(L38<'Marketplace Rules'!$A$4,'Marketplace Rules'!$B$4,IF(L38<'Marketplace Rules'!$A$5,'Marketplace Rules'!$B$5,IF(L38<'Marketplace Rules'!$A$6,'Marketplace Rules'!$B$6,'Marketplace Rules'!$B$7)))-1 -> 0.15 | N38: 299
A39: Garage Shelving | B39: Install garage storage systems | C39: Per Unit | D39: Discoun | F39: 175 | G39: One section | H39: $80 each | I39: Multi-section discount | M39: =IF(L39<'Marketplace Rules'!$A$4,'Marketplace Rules'!$B$4,IF(L39<'Marketplace Rules'!$A$5,'Marketplace Rules'!$B$5,IF(L39<'Marketplace Rules'!$A$6,'Marketplace Rules'!$B$6,'Marketplace Rules'!$B$7)))-1 -> 0.15 | N39: 299
A40: Backsplash Installation | B40: Install tile backsplash | C40: Per Unit | D40: Sq-Ft | F40: 250 | G40: 30 | H40: 6.5 | I40: 100 | J40: =H40*0.9 -> 5.85 | K40: 5 | L40: =F40+IF((I40>G40),IF(K40>G40,(K40-G40)*H40,0),IF(K40>I40,(K40-I40),0)*J40) -> 250 | M40: =IF(L40<'Marketplace Rules'!$A$4,'Marketplace Rules'!$B$4,IF(L40<'Marketplace Rules'!$A$5,'Marketplace Rules'!$B$5,IF(L40<'Marketplace Rules'!$A$6,'Marketplace Rules'!$B$6,'Marketplace Rules'!$B$7)))-1 -> 0.15 | N40: 399
...

Sheet QUoted services
A1: Quote-Based Services
A3: Service | B3: Typical Sub Cost | C3: Typical Customer Price | D3: Gross Margin
A4: Large Deck Repairs | B4: $300–2,500 | C4: $600–4,500 | D4: 35–45%
A5: Pergola Assembly | B5: $400–1,500 | C5: $700–2,750 | D5: 35–45%
A6: Gazebo Assembly | B6: $500–2,000 | C6: $900–3,500 | D6: 35–45%
A7: Crawlspace Repairs | B7: $500–5,000 | C7: $900–8,000 | D7: 35–40%
A8: Accessibility Modifications | B8: $500–10,000 | C8: $900–16,000 | D8: 35–40%
A9: Wheelchair Ramp Installation | B9: $1,000–5,000 | C9: $1,800–8,500 | D9: 35–40%
A10: Whole-House Painting | B10: $1,200–6,000 | C10: $2,000–10,000 | D10: 35–40%
A11: Seasonal Maintenance Package | B11: $200–750 | C11: $399–1,250 | D11: 35–45%

Sheet Marketplace Rules
A1: Recommended Marketplace Rules
A3: Job Cost to You | B3: Suggested Customer Multiplier
A4: 150 | B4: 1.15
A5: 500 | B5: 1.15
A6: 2000 | B6: 1.1
A7: 2000 | B7: 1.1
